2024-06-18 20:42:49,504 INFO    StreamThr :25808 [internal.py:wandb_internal():89] W&B internal server running at pid: 25808, started at: 2024-06-18 20:42:49.503213
2024-06-18 20:42:49,505 DEBUG   HandlerThread:25808 [handler.py:handle_request():144] handle_request: status
2024-06-18 20:42:49,513 INFO    WriterThread:25808 [datastore.py:open_for_write():85] open: D:\Research-Projects-jupyter\PFLlib\system\wandb\run-20240618_204249-m042hanx\run-m042hanx.wandb
2024-06-18 20:42:49,514 DEBUG   SenderThread:25808 [sender.py:send():379] send: header
2024-06-18 20:42:49,554 DEBUG   SenderThread:25808 [sender.py:send():379] send: run
2024-06-18 20:42:54,591 DEBUG   HandlerThread:25808 [handler.py:handle_request():144] handle_request: keepalive
2024-06-18 20:42:59,626 DEBUG   HandlerThread:25808 [handler.py:handle_request():144] handle_request: keepalive
2024-06-18 20:43:04,667 DEBUG   HandlerThread:25808 [handler.py:handle_request():144] handle_request: keepalive
2024-06-18 20:43:09,721 DEBUG   HandlerThread:25808 [handler.py:handle_request():144] handle_request: keepalive
2024-06-18 20:43:14,784 DEBUG   HandlerThread:25808 [handler.py:handle_request():144] handle_request: keepalive
2024-06-18 20:43:19,834 DEBUG   HandlerThread:25808 [handler.py:handle_request():144] handle_request: keepalive
2024-06-18 20:43:22,944 INFO    SenderThread:25808 [retry.py:__call__():172] Retry attempt failed:
Traceback (most recent call last):
  File "D:\Reseach Software\envs\fl\lib\site-packages\urllib3\connection.py", line 202, in _new_conn
    socket_options=self.socket_options,
  File "D:\Reseach Software\envs\fl\lib\site-packages\urllib3\util\connection.py", line 85, in create_connection
    raise err
  File "D:\Reseach Software\envs\fl\lib\site-packages\urllib3\util\connection.py", line 73, in create_connection
    sock.connect(sa)
socket.timeout: timed out

The above exception was the direct cause of the following exception:

Traceback (most recent call last):
  File "D:\Reseach Software\envs\fl\lib\site-packages\urllib3\connectionpool.py", line 805, in urlopen
    **response_kw,
  File "D:\Reseach Software\envs\fl\lib\site-packages\urllib3\connectionpool.py", line 491, in _make_request
    raise new_e
  File "D:\Reseach Software\envs\fl\lib\site-packages\urllib3\connectionpool.py", line 467, in _make_request
    self._validate_conn(conn)
  File "D:\Reseach Software\envs\fl\lib\site-packages\urllib3\connectionpool.py", line 1099, in _validate_conn
    conn.connect()
  File "D:\Reseach Software\envs\fl\lib\site-packages\urllib3\connection.py", line 616, in connect
    self.sock = sock = self._new_conn()
  File "D:\Reseach Software\envs\fl\lib\site-packages\urllib3\connection.py", line 210, in _new_conn
    ) from e
urllib3.exceptions.ConnectTimeoutError: (<urllib3.connection.HTTPSConnection object at 0x0000023B404641C8>, 'Connection to api.wandb.ai timed out. (connect timeout=10)')

The above exception was the direct cause of the following exception:

Traceback (most recent call last):
  File "D:\Reseach Software\envs\fl\lib\site-packages\requests\adapters.py", line 497, in send
    chunked=chunked,
  File "D:\Reseach Software\envs\fl\lib\site-packages\urllib3\connectionpool.py", line 848, in urlopen
    method, url, error=new_e, _pool=self, _stacktrace=sys.exc_info()[2]
  File "D:\Reseach Software\envs\fl\lib\site-packages\urllib3\util\retry.py", line 515, in increment
    raise MaxRetryError(_pool, url, reason) from reason  # type: ignore[arg-type]
urllib3.exceptions.MaxRetryError: HTTPSConnectionPool(host='api.wandb.ai', port=443): Max retries exceeded with url: /graphql (Caused by ConnectTimeoutError(<urllib3.connection.HTTPSConnection object at 0x0000023B404641C8>, 'Connection to api.wandb.ai timed out. (connect timeout=10)'))

During handling of the above exception, another exception occurred:

Traceback (most recent call last):
  File "D:\Reseach Software\envs\fl\lib\site-packages\wandb\sdk\lib\retry.py", line 131, in __call__
    result = self._call_fn(*args, **kwargs)
  File "D:\Reseach Software\envs\fl\lib\site-packages\wandb\sdk\internal\internal_api.py", line 323, in execute
    return self.client.execute(*args, **kwargs)  # type: ignore
  File "D:\Reseach Software\envs\fl\lib\site-packages\wandb\vendor\gql-0.2.0\wandb_gql\client.py", line 52, in execute
    result = self._get_result(document, *args, **kwargs)
  File "D:\Reseach Software\envs\fl\lib\site-packages\wandb\vendor\gql-0.2.0\wandb_gql\client.py", line 60, in _get_result
    return self.transport.execute(document, *args, **kwargs)
  File "D:\Reseach Software\envs\fl\lib\site-packages\wandb\sdk\lib\gql_request.py", line 55, in execute
    request = self.session.post(self.url, **post_args)
  File "D:\Reseach Software\envs\fl\lib\site-packages\requests\sessions.py", line 637, in post
    return self.request("POST", url, data=data, json=json, **kwargs)
  File "D:\Reseach Software\envs\fl\lib\site-packages\requests\sessions.py", line 589, in request
    resp = self.send(prep, **send_kwargs)
  File "D:\Reseach Software\envs\fl\lib\site-packages\requests\sessions.py", line 703, in send
    r = adapter.send(request, **kwargs)
  File "D:\Reseach Software\envs\fl\lib\site-packages\requests\adapters.py", line 507, in send
    raise ConnectTimeout(e, request=request)
requests.exceptions.ConnectTimeout: HTTPSConnectionPool(host='api.wandb.ai', port=443): Max retries exceeded with url: /graphql (Caused by ConnectTimeoutError(<urllib3.connection.HTTPSConnection object at 0x0000023B404641C8>, 'Connection to api.wandb.ai timed out. (connect timeout=10)'))
2024-06-18 20:43:24,868 DEBUG   HandlerThread:25808 [handler.py:handle_request():144] handle_request: keepalive
2024-06-18 20:43:29,905 DEBUG   HandlerThread:25808 [handler.py:handle_request():144] handle_request: keepalive
2024-06-18 20:43:34,960 DEBUG   HandlerThread:25808 [handler.py:handle_request():144] handle_request: keepalive
2024-06-18 20:43:40,016 DEBUG   HandlerThread:25808 [handler.py:handle_request():144] handle_request: keepalive
2024-06-18 20:43:45,065 DEBUG   HandlerThread:25808 [handler.py:handle_request():144] handle_request: keepalive
2024-06-18 20:43:50,111 DEBUG   HandlerThread:25808 [handler.py:handle_request():144] handle_request: cancel
2024-06-18 20:43:50,111 DEBUG   HandlerThread:25808 [handler.py:handle_request():144] handle_request: cancel
2024-06-18 20:43:55,386 DEBUG   SenderThread:25808 [sender.py:send():388] Record cancelled: run
2024-06-18 20:43:55,386 DEBUG   HandlerThread:25808 [handler.py:handle_request():144] handle_request: status_report
2024-06-18 20:44:00,429 DEBUG   HandlerThread:25808 [handler.py:handle_request():144] handle_request: status_report
2024-06-18 20:44:05,473 DEBUG   HandlerThread:25808 [handler.py:handle_request():144] handle_request: status_report
2024-06-18 20:44:10,530 DEBUG   HandlerThread:25808 [handler.py:handle_request():144] handle_request: status_report
2024-06-18 20:44:15,585 DEBUG   HandlerThread:25808 [handler.py:handle_request():144] handle_request: status_report
2024-06-18 20:44:20,623 DEBUG   HandlerThread:25808 [handler.py:handle_request():144] handle_request: status_report
2024-06-18 20:44:25,666 DEBUG   HandlerThread:25808 [handler.py:handle_request():144] handle_request: status_report
2024-06-18 20:44:30,710 DEBUG   HandlerThread:25808 [handler.py:handle_request():144] handle_request: status_report
2024-06-18 20:44:35,753 DEBUG   HandlerThread:25808 [handler.py:handle_request():144] handle_request: status_report
2024-06-18 20:44:40,800 DEBUG   HandlerThread:25808 [handler.py:handle_request():144] handle_request: status_report
2024-06-18 20:44:45,825 DEBUG   HandlerThread:25808 [handler.py:handle_request():144] handle_request: status_report
2024-06-18 20:44:50,859 DEBUG   HandlerThread:25808 [handler.py:handle_request():144] handle_request: status_report
2024-06-18 20:44:55,910 DEBUG   HandlerThread:25808 [handler.py:handle_request():144] handle_request: status_report
2024-06-18 20:45:00,940 DEBUG   HandlerThread:25808 [handler.py:handle_request():144] handle_request: status_report
2024-06-18 20:45:05,974 DEBUG   HandlerThread:25808 [handler.py:handle_request():144] handle_request: status_report
2024-06-18 20:45:11,011 DEBUG   HandlerThread:25808 [handler.py:handle_request():144] handle_request: status_report
2024-06-18 20:45:16,037 DEBUG   HandlerThread:25808 [handler.py:handle_request():144] handle_request: status_report
2024-06-18 20:45:21,086 DEBUG   HandlerThread:25808 [handler.py:handle_request():144] handle_request: status_report
2024-06-18 20:45:26,127 DEBUG   HandlerThread:25808 [handler.py:handle_request():144] handle_request: status_report
2024-06-18 20:45:31,198 DEBUG   HandlerThread:25808 [handler.py:handle_request():144] handle_request: status_report
2024-06-18 20:45:36,246 DEBUG   HandlerThread:25808 [handler.py:handle_request():144] handle_request: status_report
2024-06-18 20:45:41,299 DEBUG   HandlerThread:25808 [handler.py:handle_request():144] handle_request: status_report
2024-06-18 20:45:46,338 DEBUG   HandlerThread:25808 [handler.py:handle_request():144] handle_request: status_report
2024-06-18 20:45:51,377 DEBUG   HandlerThread:25808 [handler.py:handle_request():144] handle_request: status_report
2024-06-18 20:45:56,439 DEBUG   HandlerThread:25808 [handler.py:handle_request():144] handle_request: status_report
2024-06-18 20:46:01,471 DEBUG   HandlerThread:25808 [handler.py:handle_request():144] handle_request: status_report
2024-06-18 20:46:06,544 DEBUG   HandlerThread:25808 [handler.py:handle_request():144] handle_request: status_report
2024-06-18 20:46:11,593 DEBUG   HandlerThread:25808 [handler.py:handle_request():144] handle_request: status_report
2024-06-18 20:46:16,645 DEBUG   HandlerThread:25808 [handler.py:handle_request():144] handle_request: status_report
2024-06-18 20:46:21,689 DEBUG   HandlerThread:25808 [handler.py:handle_request():144] handle_request: status_report
2024-06-18 20:46:26,745 DEBUG   HandlerThread:25808 [handler.py:handle_request():144] handle_request: status_report
2024-06-18 20:46:31,793 DEBUG   HandlerThread:25808 [handler.py:handle_request():144] handle_request: status_report
2024-06-18 20:46:36,842 DEBUG   HandlerThread:25808 [handler.py:handle_request():144] handle_request: status_report
2024-06-18 20:46:41,896 DEBUG   HandlerThread:25808 [handler.py:handle_request():144] handle_request: status_report
2024-06-18 20:46:46,938 DEBUG   HandlerThread:25808 [handler.py:handle_request():144] handle_request: status_report
2024-06-18 20:46:52,019 DEBUG   HandlerThread:25808 [handler.py:handle_request():144] handle_request: status_report
2024-06-18 20:46:57,040 DEBUG   HandlerThread:25808 [handler.py:handle_request():144] handle_request: status_report
2024-06-18 20:47:02,086 DEBUG   HandlerThread:25808 [handler.py:handle_request():144] handle_request: status_report
2024-06-18 20:47:07,110 DEBUG   HandlerThread:25808 [handler.py:handle_request():144] handle_request: status_report
2024-06-18 20:47:12,134 DEBUG   HandlerThread:25808 [handler.py:handle_request():144] handle_request: status_report
2024-06-18 20:47:17,176 DEBUG   HandlerThread:25808 [handler.py:handle_request():144] handle_request: status_report
2024-06-18 20:47:22,214 DEBUG   HandlerThread:25808 [handler.py:handle_request():144] handle_request: status_report
2024-06-18 20:47:27,243 DEBUG   HandlerThread:25808 [handler.py:handle_request():144] handle_request: status_report
2024-06-18 20:47:32,280 DEBUG   HandlerThread:25808 [handler.py:handle_request():144] handle_request: status_report
