2024-06-18 11:46:08,576 INFO    StreamThr :32936 [internal.py:wandb_internal():89] W&B internal server running at pid: 32936, started at: 2024-06-18 11:46:08.575496
2024-06-18 11:46:08,576 DEBUG   HandlerThread:32936 [handler.py:handle_request():144] handle_request: status
2024-06-18 11:46:08,584 INFO    WriterThread:32936 [datastore.py:open_for_write():85] open: D:\Research-Projects-jupyter\PFLlib\system\wandb\run-20240618_114608-yjhabq2u\run-yjhabq2u.wandb
2024-06-18 11:46:08,585 DEBUG   SenderThread:32936 [sender.py:send():379] send: header
2024-06-18 11:46:08,625 DEBUG   SenderThread:32936 [sender.py:send():379] send: run
2024-06-18 11:46:13,675 DEBUG   HandlerThread:32936 [handler.py:handle_request():144] handle_request: keepalive
2024-06-18 11:46:18,718 DEBUG   HandlerThread:32936 [handler.py:handle_request():144] handle_request: keepalive
2024-06-18 11:46:23,762 DEBUG   HandlerThread:32936 [handler.py:handle_request():144] handle_request: keepalive
2024-06-18 11:46:28,801 DEBUG   HandlerThread:32936 [handler.py:handle_request():144] handle_request: keepalive
2024-06-18 11:46:33,851 DEBUG   HandlerThread:32936 [handler.py:handle_request():144] handle_request: keepalive
2024-06-18 11:46:38,903 DEBUG   HandlerThread:32936 [handler.py:handle_request():144] handle_request: keepalive
2024-06-18 11:46:42,088 INFO    SenderThread:32936 [retry.py:__call__():172] Retry attempt failed:
Traceback (most recent call last):
  File "D:\Reseach Software\envs\fl\lib\site-packages\urllib3\connection.py", line 202, in _new_conn
    socket_options=self.socket_options,
  File "D:\Reseach Software\envs\fl\lib\site-packages\urllib3\util\connection.py", line 85, in create_connection
    raise err
  File "D:\Reseach Software\envs\fl\lib\site-packages\urllib3\util\connection.py", line 73, in create_connection
    sock.connect(sa)
socket.timeout: timed out

The above exception was the direct cause of the following exception:

Traceback (most recent call last):
  File "D:\Reseach Software\envs\fl\lib\site-packages\urllib3\connectionpool.py", line 805, in urlopen
    **response_kw,
  File "D:\Reseach Software\envs\fl\lib\site-packages\urllib3\connectionpool.py", line 491, in _make_request
    raise new_e
  File "D:\Reseach Software\envs\fl\lib\site-packages\urllib3\connectionpool.py", line 467, in _make_request
    self._validate_conn(conn)
  File "D:\Reseach Software\envs\fl\lib\site-packages\urllib3\connectionpool.py", line 1099, in _validate_conn
    conn.connect()
  File "D:\Reseach Software\envs\fl\lib\site-packages\urllib3\connection.py", line 616, in connect
    self.sock = sock = self._new_conn()
  File "D:\Reseach Software\envs\fl\lib\site-packages\urllib3\connection.py", line 210, in _new_conn
    ) from e
urllib3.exceptions.ConnectTimeoutError: (<urllib3.connection.HTTPSConnection object at 0x000002DE856D4108>, 'Connection to api.wandb.ai timed out. (connect timeout=10)')

The above exception was the direct cause of the following exception:

Traceback (most recent call last):
  File "D:\Reseach Software\envs\fl\lib\site-packages\requests\adapters.py", line 497, in send
    chunked=chunked,
  File "D:\Reseach Software\envs\fl\lib\site-packages\urllib3\connectionpool.py", line 848, in urlopen
    method, url, error=new_e, _pool=self, _stacktrace=sys.exc_info()[2]
  File "D:\Reseach Software\envs\fl\lib\site-packages\urllib3\util\retry.py", line 515, in increment
    raise MaxRetryError(_pool, url, reason) from reason  # type: ignore[arg-type]
urllib3.exceptions.MaxRetryError: HTTPSConnectionPool(host='api.wandb.ai', port=443): Max retries exceeded with url: /graphql (Caused by ConnectTimeoutError(<urllib3.connection.HTTPSConnection object at 0x000002DE856D4108>, 'Connection to api.wandb.ai timed out. (connect timeout=10)'))

During handling of the above exception, another exception occurred:

Traceback (most recent call last):
  File "D:\Reseach Software\envs\fl\lib\site-packages\wandb\sdk\lib\retry.py", line 131, in __call__
    result = self._call_fn(*args, **kwargs)
  File "D:\Reseach Software\envs\fl\lib\site-packages\wandb\sdk\internal\internal_api.py", line 323, in execute
    return self.client.execute(*args, **kwargs)  # type: ignore
  File "D:\Reseach Software\envs\fl\lib\site-packages\wandb\vendor\gql-0.2.0\wandb_gql\client.py", line 52, in execute
    result = self._get_result(document, *args, **kwargs)
  File "D:\Reseach Software\envs\fl\lib\site-packages\wandb\vendor\gql-0.2.0\wandb_gql\client.py", line 60, in _get_result
    return self.transport.execute(document, *args, **kwargs)
  File "D:\Reseach Software\envs\fl\lib\site-packages\wandb\sdk\lib\gql_request.py", line 55, in execute
    request = self.session.post(self.url, **post_args)
  File "D:\Reseach Software\envs\fl\lib\site-packages\requests\sessions.py", line 637, in post
    return self.request("POST", url, data=data, json=json, **kwargs)
  File "D:\Reseach Software\envs\fl\lib\site-packages\requests\sessions.py", line 589, in request
    resp = self.send(prep, **send_kwargs)
  File "D:\Reseach Software\envs\fl\lib\site-packages\requests\sessions.py", line 703, in send
    r = adapter.send(request, **kwargs)
  File "D:\Reseach Software\envs\fl\lib\site-packages\requests\adapters.py", line 507, in send
    raise ConnectTimeout(e, request=request)
requests.exceptions.ConnectTimeout: HTTPSConnectionPool(host='api.wandb.ai', port=443): Max retries exceeded with url: /graphql (Caused by ConnectTimeoutError(<urllib3.connection.HTTPSConnection object at 0x000002DE856D4108>, 'Connection to api.wandb.ai timed out. (connect timeout=10)'))
2024-06-18 11:46:43,956 DEBUG   HandlerThread:32936 [handler.py:handle_request():144] handle_request: keepalive
2024-06-18 11:46:48,988 DEBUG   HandlerThread:32936 [handler.py:handle_request():144] handle_request: keepalive
2024-06-18 11:46:54,023 DEBUG   HandlerThread:32936 [handler.py:handle_request():144] handle_request: keepalive
2024-06-18 11:46:59,051 DEBUG   HandlerThread:32936 [handler.py:handle_request():144] handle_request: keepalive
2024-06-18 11:47:04,098 DEBUG   HandlerThread:32936 [handler.py:handle_request():144] handle_request: keepalive
2024-06-18 11:47:09,141 DEBUG   HandlerThread:32936 [handler.py:handle_request():144] handle_request: cancel
2024-06-18 11:47:09,141 DEBUG   HandlerThread:32936 [handler.py:handle_request():144] handle_request: cancel
2024-06-18 11:47:14,263 DEBUG   SenderThread:32936 [sender.py:send():388] Record cancelled: run
2024-06-18 11:47:14,263 DEBUG   HandlerThread:32936 [handler.py:handle_request():144] handle_request: status_report
2024-06-18 11:47:16,112 INFO    StreamThr :32936 [internal.py:wandb_internal():89] W&B internal server running at pid: 32936, started at: 2024-06-18 11:47:16.111851
2024-06-18 11:47:16,113 DEBUG   HandlerThread:32936 [handler.py:handle_request():144] handle_request: status
2024-06-18 11:47:16,119 INFO    WriterThread:32936 [datastore.py:open_for_write():85] open: D:\Research-Projects-jupyter\PFLlib\system\wandb\run-20240618_114716-txph0v8s\run-txph0v8s.wandb
2024-06-18 11:47:16,120 DEBUG   SenderThread:32936 [sender.py:send():379] send: header
2024-06-18 11:47:16,212 DEBUG   SenderThread:32936 [sender.py:send():379] send: run
2024-06-18 11:47:19,366 DEBUG   HandlerThread:32936 [handler.py:handle_request():144] handle_request: status_report
2024-06-18 11:47:21,260 DEBUG   HandlerThread:32936 [handler.py:handle_request():144] handle_request: keepalive
2024-06-18 11:47:24,420 DEBUG   HandlerThread:32936 [handler.py:handle_request():144] handle_request: status_report
2024-06-18 11:47:26,316 DEBUG   HandlerThread:32936 [handler.py:handle_request():144] handle_request: keepalive
2024-06-18 11:47:29,480 DEBUG   HandlerThread:32936 [handler.py:handle_request():144] handle_request: status_report
2024-06-18 11:47:31,358 DEBUG   HandlerThread:32936 [handler.py:handle_request():144] handle_request: keepalive
2024-06-18 11:47:34,522 DEBUG   HandlerThread:32936 [handler.py:handle_request():144] handle_request: status_report
2024-06-18 11:47:36,420 DEBUG   HandlerThread:32936 [handler.py:handle_request():144] handle_request: keepalive
2024-06-18 11:47:39,579 DEBUG   HandlerThread:32936 [handler.py:handle_request():144] handle_request: status_report
2024-06-18 11:47:40,478 INFO    SenderThread:32936 [dir_watcher.py:__init__():211] watching files in: D:\Research-Projects-jupyter\PFLlib\system\wandb\run-20240618_114716-txph0v8s\files
2024-06-18 11:47:40,478 INFO    SenderThread:32936 [sender.py:_start_run_threads():1124] run started: txph0v8s with start time 1718682436.111851
2024-06-18 11:47:40,478 DEBUG   HandlerThread:32936 [handler.py:handle_request():144] handle_request: status_report
2024-06-18 11:47:41,473 DEBUG   HandlerThread:32936 [handler.py:handle_request():144] handle_request: keepalive
2024-06-18 11:47:44,625 DEBUG   HandlerThread:32936 [handler.py:handle_request():144] handle_request: status_report
2024-06-18 11:47:45,525 DEBUG   HandlerThread:32936 [handler.py:handle_request():144] handle_request: status_report
2024-06-18 11:47:46,522 DEBUG   HandlerThread:32936 [handler.py:handle_request():144] handle_request: keepalive
2024-06-18 11:47:49,679 DEBUG   HandlerThread:32936 [handler.py:handle_request():144] handle_request: status_report
2024-06-18 11:47:50,584 DEBUG   HandlerThread:32936 [handler.py:handle_request():144] handle_request: status_report
2024-06-18 11:47:51,571 DEBUG   HandlerThread:32936 [handler.py:handle_request():144] handle_request: keepalive
2024-06-18 11:47:54,732 DEBUG   HandlerThread:32936 [handler.py:handle_request():144] handle_request: status_report
2024-06-18 11:47:55,627 DEBUG   HandlerThread:32936 [handler.py:handle_request():144] handle_request: status_report
2024-06-18 11:47:56,619 DEBUG   HandlerThread:32936 [handler.py:handle_request():144] handle_request: keepalive
2024-06-18 11:47:59,773 DEBUG   HandlerThread:32936 [handler.py:handle_request():144] handle_request: status_report
2024-06-18 11:48:00,664 DEBUG   HandlerThread:32936 [handler.py:handle_request():144] handle_request: status_report
2024-06-18 11:48:01,653 DEBUG   HandlerThread:32936 [handler.py:handle_request():144] handle_request: keepalive
2024-06-18 11:48:04,826 DEBUG   HandlerThread:32936 [handler.py:handle_request():144] handle_request: status_report
2024-06-18 11:48:05,714 DEBUG   HandlerThread:32936 [handler.py:handle_request():144] handle_request: status_report
2024-06-18 11:48:06,703 DEBUG   HandlerThread:32936 [handler.py:handle_request():144] handle_request: keepalive
2024-06-18 11:48:09,885 DEBUG   HandlerThread:32936 [handler.py:handle_request():144] handle_request: status_report
2024-06-18 11:48:10,723 WARNING FileStreamThread:32936 [file_stream.py:request_with_retry():671] requests_with_retry encountered retryable exception: HTTPSConnectionPool(host='api.wandb.ai', port=443): Max retries exceeded with url: /files/paddeyzhang/SCL_test/txph0v8s/file_stream (Caused by ProxyError('Unable to connect to proxy', SSLError(SSLError(1, '[SSL: KRB5_S_TKT_NYV] unexpected eof while reading (_ssl.c:1091)')))). func: functools.partial(<bound method Session.post of <requests.sessions.Session object at 0x000002DE85794F08>>, timeout=60.0), args: ('https://api.wandb.ai/files/paddeyzhang/SCL_test/txph0v8s/file_stream',), kwargs: {'json': {'complete': False, 'failed': False, 'dropped': 0, 'uploaded': []}}
2024-06-18 11:48:10,751 DEBUG   HandlerThread:32936 [handler.py:handle_request():144] handle_request: status_report
2024-06-18 11:48:11,744 DEBUG   HandlerThread:32936 [handler.py:handle_request():144] handle_request: keepalive
