2024-06-18 16:05:00,504 INFO    MainThread:11216 [wandb_setup.py:_flush():76] Current SDK version is 0.15.8
2024-06-18 16:05:00,504 INFO    MainThread:11216 [wandb_setup.py:_flush():76] Configure stats pid to 11216
2024-06-18 16:05:00,504 INFO    MainThread:11216 [wandb_setup.py:_flush():76] Loading settings from C:\Users\ly\.config\wandb\settings
2024-06-18 16:05:00,504 INFO    MainThread:11216 [wandb_setup.py:_flush():76] Loading settings from D:\Research-Projects-jupyter\PFLlib\system\wandb\settings
2024-06-18 16:05:00,504 INFO    MainThread:11216 [wandb_setup.py:_flush():76] Loading settings from environment variables: {}
2024-06-18 16:05:00,504 INFO    MainThread:11216 [wandb_setup.py:_flush():76] Inferring run settings from compute environment: {'program_relpath': 'system\\main.py', 'program': 'D:\\Research-Projects-jupyter\\PFLlib\\system\\main.py'}
2024-06-18 16:05:00,504 INFO    MainThread:11216 [wandb_init.py:_log_setup():507] Logging user logs to D:\Research-Projects-jupyter\PFLlib\system\wandb\run-20240618_160500-kh8j2obt\logs\debug.log
2024-06-18 16:05:00,504 INFO    MainThread:11216 [wandb_init.py:_log_setup():508] Logging internal logs to D:\Research-Projects-jupyter\PFLlib\system\wandb\run-20240618_160500-kh8j2obt\logs\debug-internal.log
2024-06-18 16:05:00,505 INFO    MainThread:11216 [wandb_init.py:_jupyter_setup():453] configuring jupyter hooks <wandb.sdk.wandb_init._WandbInit object at 0x000001B27B1F4308>
2024-06-18 16:05:00,505 INFO    MainThread:11216 [wandb_init.py:init():547] calling init triggers
2024-06-18 16:05:00,505 INFO    MainThread:11216 [wandb_init.py:init():555] wandb.init called with sweep_config: {}
config: {'goal': 'test', 'device': 'cuda', 'device_id': '0', 'dataset': 'Cifar10', 'num_classes': 10, 'model': BaseHeadSplit(
  (base): FedAvgCNN(
    (conv1): Sequential(
      (0): Conv2d(3, 32, kernel_size=(5, 5), stride=(1, 1))
      (1): ReLU(inplace=True)
      (2): MaxPool2d(kernel_size=(2, 2), stride=(2, 2), padding=0, dilation=1, ceil_mode=False)
    )
    (conv2): Sequential(
      (0): Conv2d(32, 64, kernel_size=(5, 5), stride=(1, 1))
      (1): ReLU(inplace=True)
      (2): MaxPool2d(kernel_size=(2, 2), stride=(2, 2), padding=0, dilation=1, ceil_mode=False)
    )
    (fc1): Sequential(
      (0): Linear(in_features=1600, out_features=512, bias=True)
      (1): ReLU(inplace=True)
    )
    (fc): Identity()
  )
  (head): Linear(in_features=512, out_features=10, bias=True)
), 'batch_size': 64, 'local_learning_rate': 0.005, 'learning_rate_decay': False, 'learning_rate_decay_gamma': 0.99, 'global_rounds': 1000, 'local_epochs': 1, 'algorithm': 'FedASCL', 'join_ratio': 1.0, 'random_join_ratio': False, 'num_clients': 20, 'prev': 0, 'times': 1, 'eval_gap': 10, 'save_folder_name': 'items', 'auto_break': False, 'dlg_eval': False, 'dlg_gap': 100, 'batch_num_per_client': 2, 'num_new_clients': 0, 'fine_tuning_epoch_new': 0, 'client_drop_rate': 0.0, 'train_slow_rate': 0.0, 'send_slow_rate': 0.0, 'time_select': False, 'time_threthold': 10000, 'beta': 0.0, 'lamda': 1.0, 'mu': 0.0, 'K': 5, 'p_learning_rate': 0.01, 'M': 5, 'itk': 4000, 'alphaK': 1.0, 'sigma': 1.0, 'alpha': 1.0, 'plocal_epochs': 1, 'tau': 1.0, 'fine_tuning_epochs': 10, 'dr_learning_rate': 0.0, 'L': 1.0, 'noise_dim': 512, 'generator_learning_rate': 0.005, 'hidden_dim': 512, 'server_epochs': 1000, 'localize_feature_extractor': False, 'server_learning_rate': 1.0, 'eta': 1.0, 'rand_percent': 80, 'layer_idx': 2, 'mentee_learning_rate': 0.005, 'T_start': 0.95, 'T_end': 0.98, 'momentum': 0.1, 'kl_weight': 0.0, 'wandb': 'SCL_test', 'margin_type': 'cNCE', 'n_views': 2, 'model_str': 'cnn', 'head': Linear(in_features=512, out_features=10, bias=True)}
2024-06-18 16:05:00,505 INFO    MainThread:11216 [wandb_init.py:init():596] starting backend
2024-06-18 16:05:00,505 INFO    MainThread:11216 [wandb_init.py:init():600] setting up manager
2024-06-18 16:05:00,507 INFO    MainThread:11216 [backend.py:_multiprocessing_setup():108] multiprocessing start_methods=spawn, using: spawn
2024-06-18 16:05:00,508 INFO    MainThread:11216 [wandb_init.py:init():606] backend started and connected
2024-06-18 16:05:00,518 INFO    MainThread:11216 [wandb_run.py:_label_probe_notebook():1234] probe notebook
2024-06-18 16:05:00,519 INFO    MainThread:11216 [wandb_run.py:_label_probe_notebook():1244] Unable to probe notebook: 'NoneType' object has no attribute 'get'
2024-06-18 16:05:00,519 INFO    MainThread:11216 [wandb_init.py:init():697] updated telemetry
2024-06-18 16:05:00,562 INFO    MainThread:11216 [wandb_init.py:init():730] communicating run to backend with 60.0 second timeout
2024-06-18 16:05:17,937 INFO    Thread-11 :11216 [retry.py:__call__():172] Retry attempt failed:
urllib3.exceptions.SSLError: [SSL: KRB5_S_TKT_NYV] unexpected eof while reading (_ssl.c:1091)

The above exception was the direct cause of the following exception:

urllib3.exceptions.ProxyError: ('Unable to connect to proxy', SSLError(SSLError(1, '[SSL: KRB5_S_TKT_NYV] unexpected eof while reading (_ssl.c:1091)')))

The above exception was the direct cause of the following exception:

Traceback (most recent call last):
  File "D:\Reseach Software\envs\fl\lib\site-packages\requests\adapters.py", line 497, in send
    chunked=chunked,
  File "D:\Reseach Software\envs\fl\lib\site-packages\urllib3\connectionpool.py", line 848, in urlopen
    method, url, error=new_e, _pool=self, _stacktrace=sys.exc_info()[2]
  File "D:\Reseach Software\envs\fl\lib\site-packages\urllib3\util\retry.py", line 515, in increment
    raise MaxRetryError(_pool, url, reason) from reason  # type: ignore[arg-type]
urllib3.exceptions.MaxRetryError: HTTPSConnectionPool(host='api.wandb.ai', port=443): Max retries exceeded with url: /graphql (Caused by ProxyError('Unable to connect to proxy', SSLError(SSLError(1, '[SSL: KRB5_S_TKT_NYV] unexpected eof while reading (_ssl.c:1091)'))))

During handling of the above exception, another exception occurred:

Traceback (most recent call last):
  File "D:\Reseach Software\envs\fl\lib\site-packages\wandb\sdk\lib\retry.py", line 131, in __call__
    result = self._call_fn(*args, **kwargs)
  File "D:\Reseach Software\envs\fl\lib\site-packages\wandb\sdk\internal\internal_api.py", line 323, in execute
    return self.client.execute(*args, **kwargs)  # type: ignore
  File "D:\Reseach Software\envs\fl\lib\site-packages\wandb\vendor\gql-0.2.0\wandb_gql\client.py", line 52, in execute
    result = self._get_result(document, *args, **kwargs)
  File "D:\Reseach Software\envs\fl\lib\site-packages\wandb\vendor\gql-0.2.0\wandb_gql\client.py", line 60, in _get_result
    return self.transport.execute(document, *args, **kwargs)
  File "D:\Reseach Software\envs\fl\lib\site-packages\wandb\sdk\lib\gql_request.py", line 55, in execute
    request = self.session.post(self.url, **post_args)
  File "D:\Reseach Software\envs\fl\lib\site-packages\requests\sessions.py", line 637, in post
    return self.request("POST", url, data=data, json=json, **kwargs)
  File "D:\Reseach Software\envs\fl\lib\site-packages\requests\sessions.py", line 589, in request
    resp = self.send(prep, **send_kwargs)
  File "D:\Reseach Software\envs\fl\lib\site-packages\requests\sessions.py", line 703, in send
    r = adapter.send(request, **kwargs)
  File "D:\Reseach Software\envs\fl\lib\site-packages\requests\adapters.py", line 513, in send
    raise ProxyError(e, request=request)
requests.exceptions.ProxyError: HTTPSConnectionPool(host='api.wandb.ai', port=443): Max retries exceeded with url: /graphql (Caused by ProxyError('Unable to connect to proxy', SSLError(SSLError(1, '[SSL: KRB5_S_TKT_NYV] unexpected eof while reading (_ssl.c:1091)'))))
2024-06-18 16:06:01,107 ERROR   MainThread:11216 [wandb_init.py:init():756] encountered error: Run initialization has timed out after 60.0 sec. 
Please refer to the documentation for additional information: https://docs.wandb.ai/guides/track/tracking-faq#initstarterror-error-communicating-with-wandb-process-
2024-06-18 16:06:01,418 ERROR   MainThread:11216 [wandb_init.py:init():1165] Run initialization has timed out after 60.0 sec. 
Please refer to the documentation for additional information: https://docs.wandb.ai/guides/track/tracking-faq#initstarterror-error-communicating-with-wandb-process-
Traceback (most recent call last):
  File "D:\Reseach Software\envs\fl\lib\site-packages\wandb\sdk\wandb_init.py", line 1147, in init
    run = wi.init()
  File "D:\Reseach Software\envs\fl\lib\site-packages\wandb\sdk\wandb_init.py", line 762, in init
    raise error
wandb.errors.CommError: Run initialization has timed out after 60.0 sec. 
Please refer to the documentation for additional information: https://docs.wandb.ai/guides/track/tracking-faq#initstarterror-error-communicating-with-wandb-process-
2024-06-18 16:06:06,075 WARNING MsgRouterThr:11216 [router.py:message_loop():77] message_loop has been closed
