2024-06-18 17:09:00,248 INFO    StreamThr :25680 [internal.py:wandb_internal():89] W&B internal server running at pid: 25680, started at: 2024-06-18 17:09:00.247075
2024-06-18 17:09:00,249 DEBUG   HandlerThread:25680 [handler.py:handle_request():144] handle_request: status
2024-06-18 17:09:00,256 INFO    WriterThread:25680 [datastore.py:open_for_write():85] open: D:\Research-Projects-jupyter\PFLlib\system\wandb\run-20240618_170900-ecr8evyz\run-ecr8evyz.wandb
2024-06-18 17:09:00,257 DEBUG   SenderThread:25680 [sender.py:send():379] send: header
2024-06-18 17:09:00,297 DEBUG   SenderThread:25680 [sender.py:send():379] send: run
2024-06-18 17:09:01,044 INFO    SenderThread:25680 [dir_watcher.py:__init__():211] watching files in: D:\Research-Projects-jupyter\PFLlib\system\wandb\run-20240618_170900-ecr8evyz\files
2024-06-18 17:09:01,045 INFO    SenderThread:25680 [sender.py:_start_run_threads():1124] run started: ecr8evyz with start time 1718701740.248071
2024-06-18 17:09:01,045 DEBUG   SenderThread:25680 [sender.py:send_request():406] send_request: summary_record
2024-06-18 17:09:01,045 INFO    SenderThread:25680 [sender.py:_save_file():1375] saving file wandb-summary.json with policy end
2024-06-18 17:09:01,054 DEBUG   HandlerThread:25680 [handler.py:handle_request():144] handle_request: check_version
2024-06-18 17:09:01,055 DEBUG   SenderThread:25680 [sender.py:send_request():406] send_request: check_version
2024-06-18 17:09:01,562 DEBUG   HandlerThread:25680 [handler.py:handle_request():144] handle_request: run_start
2024-06-18 17:09:01,578 DEBUG   HandlerThread:25680 [system_info.py:__init__():31] System info init
2024-06-18 17:09:01,578 DEBUG   HandlerThread:25680 [system_info.py:__init__():46] System info init done
2024-06-18 17:09:01,579 INFO    HandlerThread:25680 [system_monitor.py:start():181] Starting system monitor
2024-06-18 17:09:01,579 INFO    SystemMonitor:25680 [system_monitor.py:_start():145] Starting system asset monitoring threads
2024-06-18 17:09:01,579 INFO    HandlerThread:25680 [system_monitor.py:probe():201] Collecting system info
2024-06-18 17:09:01,583 INFO    SystemMonitor:25680 [interfaces.py:start():190] Started cpu monitoring
2024-06-18 17:09:01,583 INFO    SystemMonitor:25680 [interfaces.py:start():190] Started disk monitoring
2024-06-18 17:09:01,583 INFO    SystemMonitor:25680 [interfaces.py:start():190] Started gpu monitoring
2024-06-18 17:09:01,583 INFO    SystemMonitor:25680 [interfaces.py:start():190] Started memory monitoring
2024-06-18 17:09:01,591 INFO    SystemMonitor:25680 [interfaces.py:start():190] Started network monitoring
2024-06-18 17:09:01,604 DEBUG   HandlerThread:25680 [system_info.py:probe():195] Probing system
2024-06-18 17:09:01,605 DEBUG   HandlerThread:25680 [system_info.py:_probe_git():180] Probing git
2024-06-18 17:09:01,682 DEBUG   HandlerThread:25680 [system_info.py:_probe_git():188] Probing git done
2024-06-18 17:09:01,682 DEBUG   HandlerThread:25680 [system_info.py:probe():240] Probing system done
2024-06-18 17:09:01,683 DEBUG   HandlerThread:25680 [system_monitor.py:probe():210] {'os': 'Windows-10-10.0.19041-SP0', 'python': '3.7.12', 'heartbeatAt': '2024-06-18T09:09:01.604287', 'startedAt': '2024-06-18T09:09:00.241094', 'docker': None, 'cuda': None, 'args': (), 'state': 'running', 'program': 'D:\\Research-Projects-jupyter\\PFLlib\\system\\main.py', 'codePath': 'system\\main.py', 'git': {'remote': 'https://github.com/TsingZ0/PFLlib.git', 'commit': '004a405da7c159e843d98b2a53e2114d4f859912'}, 'email': '1731485214@qq.com', 'root': 'D:/Research-Projects-jupyter/PFLlib', 'host': 'DESKTOP-4LOGPS7', 'username': 'paddeyzhang', 'executable': 'D:\\Reseach Software\\envs\\fl\\python.exe', 'cpu_count': 6, 'cpu_count_logical': 12, 'cpu_freq': {'current': 2500.0, 'min': 0.0, 'max': 2500.0}, 'cpu_freq_per_core': [{'current': 2500.0, 'min': 0.0, 'max': 2500.0}], 'disk': {'total': 199.99901962280273, 'used': 69.32249069213867}, 'gpu': 'NVIDIA GeForce RTX 3070', 'gpu_count': 1, 'gpu_devices': [{'name': 'NVIDIA GeForce RTX 3070', 'memory_total': 8589934592}], 'memory': {'total': 15.842487335205078}}
2024-06-18 17:09:01,683 INFO    HandlerThread:25680 [system_monitor.py:probe():211] Finished collecting system info
2024-06-18 17:09:01,683 INFO    HandlerThread:25680 [system_monitor.py:probe():214] Publishing system info
2024-06-18 17:09:01,683 DEBUG   HandlerThread:25680 [system_info.py:_save_pip():52] Saving list of pip packages installed into the current environment
2024-06-18 17:09:01,683 DEBUG   HandlerThread:25680 [system_info.py:_save_pip():67] Saving pip packages done
2024-06-18 17:09:01,683 DEBUG   HandlerThread:25680 [system_info.py:_save_conda():75] Saving list of conda packages installed into the current environment
2024-06-18 17:09:01,684 ERROR   HandlerThread:25680 [system_info.py:_save_conda():85] Error saving conda packages: [WinError 2] 系统找不到指定的文件。
Traceback (most recent call last):
  File "D:\Reseach Software\envs\fl\lib\site-packages\wandb\sdk\internal\system\system_info.py", line 82, in _save_conda
    ["conda", "env", "export"], stdout=f, stderr=subprocess.DEVNULL
  File "D:\Reseach Software\envs\fl\lib\subprocess.py", line 339, in call
    with Popen(*popenargs, **kwargs) as p:
  File "D:\Reseach Software\envs\fl\lib\subprocess.py", line 800, in __init__
    restore_signals, start_new_session)
  File "D:\Reseach Software\envs\fl\lib\subprocess.py", line 1207, in _execute_child
    startupinfo)
FileNotFoundError: [WinError 2] 系统找不到指定的文件。
2024-06-18 17:09:01,685 DEBUG   HandlerThread:25680 [system_info.py:_save_conda():86] Saving conda packages done
2024-06-18 17:09:01,685 DEBUG   HandlerThread:25680 [system_info.py:_save_code():89] Saving code
2024-06-18 17:09:01,723 DEBUG   HandlerThread:25680 [system_info.py:_save_code():110] Saving code done
2024-06-18 17:09:01,724 DEBUG   HandlerThread:25680 [system_info.py:_save_patches():127] Saving git patches
2024-06-18 17:09:02,060 INFO    Thread-16 :25680 [dir_watcher.py:_on_file_created():271] file/dir created: D:\Research-Projects-jupyter\PFLlib\system\wandb\run-20240618_170900-ecr8evyz\files\wandb-summary.json
2024-06-18 17:09:02,061 INFO    Thread-16 :25680 [dir_watcher.py:_on_file_created():271] file/dir created: D:\Research-Projects-jupyter\PFLlib\system\wandb\run-20240618_170900-ecr8evyz\files\requirements.txt
2024-06-18 17:09:02,061 INFO    Thread-16 :25680 [dir_watcher.py:_on_file_created():271] file/dir created: D:\Research-Projects-jupyter\PFLlib\system\wandb\run-20240618_170900-ecr8evyz\files\conda-environment.yaml
2024-06-18 17:09:02,061 INFO    Thread-16 :25680 [dir_watcher.py:_on_file_created():271] file/dir created: D:\Research-Projects-jupyter\PFLlib\system\wandb\run-20240618_170900-ecr8evyz\files\code\system\main.py
2024-06-18 17:09:02,061 INFO    Thread-16 :25680 [dir_watcher.py:_on_file_created():271] file/dir created: D:\Research-Projects-jupyter\PFLlib\system\wandb\run-20240618_170900-ecr8evyz\files\code\system
2024-06-18 17:09:02,061 INFO    Thread-16 :25680 [dir_watcher.py:_on_file_created():271] file/dir created: D:\Research-Projects-jupyter\PFLlib\system\wandb\run-20240618_170900-ecr8evyz\files\code
2024-06-18 17:09:02,645 DEBUG   HandlerThread:25680 [system_info.py:_save_patches():169] Saving git patches done
2024-06-18 17:09:02,646 INFO    HandlerThread:25680 [system_monitor.py:probe():216] Finished publishing system info
2024-06-18 17:09:02,649 DEBUG   SenderThread:25680 [sender.py:send():379] send: files
2024-06-18 17:09:02,649 INFO    SenderThread:25680 [sender.py:_save_file():1375] saving file wandb-metadata.json with policy now
2024-06-18 17:09:02,649 INFO    SenderThread:25680 [sender.py:_save_file():1375] saving file code\system\main.py with policy now
2024-06-18 17:09:02,650 INFO    SenderThread:25680 [sender.py:_save_file():1375] saving file diff.patch with policy now
2024-06-18 17:09:02,663 DEBUG   HandlerThread:25680 [handler.py:handle_request():144] handle_request: stop_status
2024-06-18 17:09:02,663 DEBUG   SenderThread:25680 [sender.py:send_request():406] send_request: stop_status
2024-06-18 17:09:03,073 INFO    Thread-16 :25680 [dir_watcher.py:_on_file_created():271] file/dir created: D:\Research-Projects-jupyter\PFLlib\system\wandb\run-20240618_170900-ecr8evyz\files\diff.patch
2024-06-18 17:09:03,073 INFO    Thread-16 :25680 [dir_watcher.py:_on_file_created():271] file/dir created: D:\Research-Projects-jupyter\PFLlib\system\wandb\run-20240618_170900-ecr8evyz\files\wandb-metadata.json
2024-06-18 17:09:03,263 DEBUG   SenderThread:25680 [sender.py:send():379] send: telemetry
2024-06-18 17:09:03,779 INFO    wandb-upload_0:25680 [upload_job.py:push():131] Uploaded file C:\Users\ly\AppData\Local\Temp\tmpt8hd81amwandb\fsc1p693-wandb-metadata.json
2024-06-18 17:09:05,267 DEBUG   HandlerThread:25680 [handler.py:handle_request():144] handle_request: status_report
2024-06-18 17:09:07,087 INFO    Thread-16 :25680 [dir_watcher.py:_on_file_created():271] file/dir created: D:\Research-Projects-jupyter\PFLlib\system\wandb\run-20240618_170900-ecr8evyz\files\output.log
2024-06-18 17:09:08,101 INFO    Thread-16 :25680 [dir_watcher.py:_on_file_modified():288] file/dir modified: D:\Research-Projects-jupyter\PFLlib\system\wandb\run-20240618_170900-ecr8evyz\files\output.log
2024-06-18 17:09:11,131 DEBUG   HandlerThread:25680 [handler.py:handle_request():144] handle_request: status_report
2024-06-18 17:09:16,190 DEBUG   HandlerThread:25680 [handler.py:handle_request():144] handle_request: status_report
2024-06-18 17:09:17,675 DEBUG   HandlerThread:25680 [handler.py:handle_request():144] handle_request: stop_status
2024-06-18 17:09:17,676 DEBUG   SenderThread:25680 [sender.py:send_request():406] send_request: stop_status
2024-06-18 17:09:22,020 DEBUG   HandlerThread:25680 [handler.py:handle_request():144] handle_request: status_report
2024-06-18 17:09:22,818 ERROR   wandb-upload_1:25680 [internal_api.py:upload_file():2496] upload_file exception https://storage.googleapis.com/wandb-production.appspot.com/paddeyzhang/SCL_test/ecr8evyz/code/system/main.py?Expires=1718788147&GoogleAccessId=gorilla-files-url-signer-man%40wandb-production.iam.gserviceaccount.com&Signature=Ik5M4n9maV0Y5LbDSawH8FYvoKicE49PHG0YAXerMPEJQETy7caAXVQmdyrV36Qw1k3xZkjXnBWnhhAPSgON1rlgSP%2F8dO2puU8Qnv5Z0s8%2BT%2F0K0cATFdIztudL4cuX9m3KZML1OU4%2BB2VLUn1%2BPidCieHgIulhwYKBc8%2FEUlgG8cNLvm%2BzUb1nJQWGi4f54W%2BvHOCqyIBqMQx9C3RarKjL%2FVaCCAUZ94UcAMQxe6f6Jw%2BeqTWNrloxkgF4oNEwsdQSlfluCS%2BDHOBzloaNw3EgZILb6jthiPH8ae1fNuEozBm3sjR6thTkoVvzWoLBr99c1GD%2FGq057roWPyoQdw%3D%3D: ('Connection aborted.', TimeoutError(10060, '由于连接方在一段时间后没有正确答复或连接的主机没有反应，连接尝试失败。', None, 10060, None))
2024-06-18 17:09:22,819 ERROR   wandb-upload_1:25680 [internal_api.py:upload_file():2498] upload_file request headers: {'User-Agent': 'python-requests/2.31.0', 'Accept-Encoding': 'gzip, deflate, br', 'Accept': '*/*', 'Connection': 'keep-alive', 'Content-Length': '25241'}
2024-06-18 17:09:22,819 ERROR   wandb-upload_1:25680 [internal_api.py:upload_file():2500] upload_file response body: 
2024-06-18 17:09:22,990 ERROR   wandb-upload_2:25680 [internal_api.py:upload_file():2496] upload_file exception https://storage.googleapis.com/wandb-production.appspot.com/paddeyzhang/SCL_test/ecr8evyz/diff.patch?Expires=1718788147&GoogleAccessId=gorilla-files-url-signer-man%40wandb-production.iam.gserviceaccount.com&Signature=N%2FaBkzixwUvbcZX49uOjFkBk4rwwFBy1bo2CTIxcrVLHWlDgPEZVrzuWJVoVccVy9PWFquAJGIxQrsqsGv9Znvtjr7BjQxijiMf6uf6z9L56VQOuWXa6IdER9AtVUmWAFARtQvUa1kGTuV5QGxyL70Y1idm1KH9ll4Zv9LiQGGzHPTg4FJE%2BxgQ7gRzr9%2Ft1vvgvmTz3Zqv5VO%2BQHECWdXC%2F4A%2B%2BprWK4W%2FzB%2FSIEdGlwNEH%2Bj4%2F0rs1bE3JeeVhNDBbahv3%2BtKG701PuCKm2oqcV2EmWqFR7Z8bzVJuVAzg4uvkV5ZMErVeTG9SRiU4dU9nFMWwp8GRlWZbS2LeWg%3D%3D: ('Connection aborted.', TimeoutError(10060, '由于连接方在一段时间后没有正确答复或连接的主机没有反应，连接尝试失败。', None, 10060, None))
2024-06-18 17:09:22,990 ERROR   wandb-upload_2:25680 [internal_api.py:upload_file():2498] upload_file request headers: {'User-Agent': 'python-requests/2.31.0', 'Accept-Encoding': 'gzip, deflate, br', 'Accept': '*/*', 'Connection': 'keep-alive', 'Content-Length': '8019'}
2024-06-18 17:09:22,990 ERROR   wandb-upload_2:25680 [internal_api.py:upload_file():2500] upload_file response body: 
2024-06-18 17:09:27,044 DEBUG   HandlerThread:25680 [handler.py:handle_request():144] handle_request: status_report
2024-06-18 17:09:32,097 DEBUG   HandlerThread:25680 [handler.py:handle_request():144] handle_request: status_report
2024-06-18 17:09:32,676 DEBUG   HandlerThread:25680 [handler.py:handle_request():144] handle_request: stop_status
2024-06-18 17:09:32,677 DEBUG   SenderThread:25680 [sender.py:send_request():406] send_request: stop_status
2024-06-18 17:09:33,309 INFO    Thread-16 :25680 [dir_watcher.py:_on_file_modified():288] file/dir modified: D:\Research-Projects-jupyter\PFLlib\system\wandb\run-20240618_170900-ecr8evyz\files\config.yaml
2024-06-18 17:09:38,018 DEBUG   HandlerThread:25680 [handler.py:handle_request():144] handle_request: status_report
2024-06-18 17:09:43,084 DEBUG   HandlerThread:25680 [handler.py:handle_request():144] handle_request: status_report
2024-06-18 17:09:43,241 ERROR   wandb-upload_1:25680 [internal_api.py:upload_file():2496] upload_file exception https://storage.googleapis.com/wandb-production.appspot.com/paddeyzhang/SCL_test/ecr8evyz/code/system/main.py?Expires=1718788147&GoogleAccessId=gorilla-files-url-signer-man%40wandb-production.iam.gserviceaccount.com&Signature=Ik5M4n9maV0Y5LbDSawH8FYvoKicE49PHG0YAXerMPEJQETy7caAXVQmdyrV36Qw1k3xZkjXnBWnhhAPSgON1rlgSP%2F8dO2puU8Qnv5Z0s8%2BT%2F0K0cATFdIztudL4cuX9m3KZML1OU4%2BB2VLUn1%2BPidCieHgIulhwYKBc8%2FEUlgG8cNLvm%2BzUb1nJQWGi4f54W%2BvHOCqyIBqMQx9C3RarKjL%2FVaCCAUZ94UcAMQxe6f6Jw%2BeqTWNrloxkgF4oNEwsdQSlfluCS%2BDHOBzloaNw3EgZILb6jthiPH8ae1fNuEozBm3sjR6thTkoVvzWoLBr99c1GD%2FGq057roWPyoQdw%3D%3D: ('Connection aborted.', TimeoutError(10060, '由于连接方在一段时间后没有正确答复或连接的主机没有反应，连接尝试失败。', None, 10060, None))
2024-06-18 17:09:43,241 ERROR   wandb-upload_1:25680 [internal_api.py:upload_file():2498] upload_file request headers: {'User-Agent': 'python-requests/2.31.0', 'Accept-Encoding': 'gzip, deflate, br', 'Accept': '*/*', 'Connection': 'keep-alive', 'Content-Length': '25241'}
2024-06-18 17:09:43,241 ERROR   wandb-upload_1:25680 [internal_api.py:upload_file():2500] upload_file response body: 
2024-06-18 17:09:43,241 INFO    wandb-upload_1:25680 [retry.py:__call__():172] Retry attempt failed:
Traceback (most recent call last):
  File "D:\Reseach Software\envs\fl\lib\site-packages\urllib3\connectionpool.py", line 805, in urlopen
    **response_kw,
  File "D:\Reseach Software\envs\fl\lib\site-packages\urllib3\connectionpool.py", line 537, in _make_request
    response = conn.getresponse()
  File "D:\Reseach Software\envs\fl\lib\site-packages\urllib3\connection.py", line 466, in getresponse
    httplib_response = super().getresponse()
  File "D:\Reseach Software\envs\fl\lib\http\client.py", line 1373, in getresponse
    response.begin()
  File "D:\Reseach Software\envs\fl\lib\http\client.py", line 319, in begin
    version, status, reason = self._read_status()
  File "D:\Reseach Software\envs\fl\lib\http\client.py", line 280, in _read_status
    line = str(self.fp.readline(_MAXLINE + 1), "iso-8859-1")
  File "D:\Reseach Software\envs\fl\lib\socket.py", line 589, in readinto
    return self._sock.recv_into(b)
  File "D:\Reseach Software\envs\fl\lib\ssl.py", line 1071, in recv_into
    return self.read(nbytes, buffer)
  File "D:\Reseach Software\envs\fl\lib\ssl.py", line 929, in read
    return self._sslobj.read(len, buffer)
TimeoutError: [WinError 10060] 由于连接方在一段时间后没有正确答复或连接的主机没有反应，连接尝试失败。

During handling of the above exception, another exception occurred:

Traceback (most recent call last):
  File "D:\Reseach Software\envs\fl\lib\site-packages\requests\adapters.py", line 497, in send
    chunked=chunked,
  File "D:\Reseach Software\envs\fl\lib\site-packages\urllib3\connectionpool.py", line 848, in urlopen
    method, url, error=new_e, _pool=self, _stacktrace=sys.exc_info()[2]
  File "D:\Reseach Software\envs\fl\lib\site-packages\urllib3\util\retry.py", line 470, in increment
    raise reraise(type(error), error, _stacktrace)
  File "D:\Reseach Software\envs\fl\lib\site-packages\urllib3\util\util.py", line 38, in reraise
    raise value.with_traceback(tb)
  File "D:\Reseach Software\envs\fl\lib\site-packages\urllib3\connectionpool.py", line 805, in urlopen
    **response_kw,
  File "D:\Reseach Software\envs\fl\lib\site-packages\urllib3\connectionpool.py", line 537, in _make_request
    response = conn.getresponse()
  File "D:\Reseach Software\envs\fl\lib\site-packages\urllib3\connection.py", line 466, in getresponse
    httplib_response = super().getresponse()
  File "D:\Reseach Software\envs\fl\lib\http\client.py", line 1373, in getresponse
    response.begin()
  File "D:\Reseach Software\envs\fl\lib\http\client.py", line 319, in begin
    version, status, reason = self._read_status()
  File "D:\Reseach Software\envs\fl\lib\http\client.py", line 280, in _read_status
    line = str(self.fp.readline(_MAXLINE + 1), "iso-8859-1")
  File "D:\Reseach Software\envs\fl\lib\socket.py", line 589, in readinto
    return self._sock.recv_into(b)
  File "D:\Reseach Software\envs\fl\lib\ssl.py", line 1071, in recv_into
    return self.read(nbytes, buffer)
  File "D:\Reseach Software\envs\fl\lib\ssl.py", line 929, in read
    return self._sslobj.read(len, buffer)
urllib3.exceptions.ProtocolError: ('Connection aborted.', TimeoutError(10060, '由于连接方在一段时间后没有正确答复或连接的主机没有反应，连接尝试失败。', None, 10060, None))

During handling of the above exception, another exception occurred:

Traceback (most recent call last):
  File "D:\Reseach Software\envs\fl\lib\site-packages\wandb\sdk\internal\internal_api.py", line 2492, in upload_file
    url, data=progress, headers=extra_headers
  File "D:\Reseach Software\envs\fl\lib\site-packages\requests\sessions.py", line 649, in put
    return self.request("PUT", url, data=data, **kwargs)
  File "D:\Reseach Software\envs\fl\lib\site-packages\requests\sessions.py", line 589, in request
    resp = self.send(prep, **send_kwargs)
  File "D:\Reseach Software\envs\fl\lib\site-packages\requests\sessions.py", line 703, in send
    r = adapter.send(request, **kwargs)
  File "D:\Reseach Software\envs\fl\lib\site-packages\requests\adapters.py", line 501, in send
    raise ConnectionError(err, request=request)
requests.exceptions.ConnectionError: ('Connection aborted.', TimeoutError(10060, '由于连接方在一段时间后没有正确答复或连接的主机没有反应，连接尝试失败。', None, 10060, None))

During handling of the above exception, another exception occurred:

Traceback (most recent call last):
  File "D:\Reseach Software\envs\fl\lib\site-packages\wandb\sdk\lib\retry.py", line 131, in __call__
    result = self._call_fn(*args, **kwargs)
  File "D:\Reseach Software\envs\fl\lib\site-packages\wandb\sdk\internal\internal_api.py", line 2520, in upload_file
    raise _e.with_traceback(sys.exc_info()[2])
  File "D:\Reseach Software\envs\fl\lib\site-packages\wandb\sdk\internal\internal_api.py", line 2492, in upload_file
    url, data=progress, headers=extra_headers
  File "D:\Reseach Software\envs\fl\lib\site-packages\requests\sessions.py", line 649, in put
    return self.request("PUT", url, data=data, **kwargs)
  File "D:\Reseach Software\envs\fl\lib\site-packages\requests\sessions.py", line 589, in request
    resp = self.send(prep, **send_kwargs)
  File "D:\Reseach Software\envs\fl\lib\site-packages\requests\sessions.py", line 703, in send
    r = adapter.send(request, **kwargs)
  File "D:\Reseach Software\envs\fl\lib\site-packages\requests\adapters.py", line 501, in send
    raise ConnectionError(err, request=request)
wandb.sdk.lib.retry.TransientError: None
2024-06-18 17:09:43,541 ERROR   wandb-upload_2:25680 [internal_api.py:upload_file():2496] upload_file exception https://storage.googleapis.com/wandb-production.appspot.com/paddeyzhang/SCL_test/ecr8evyz/diff.patch?Expires=1718788147&GoogleAccessId=gorilla-files-url-signer-man%40wandb-production.iam.gserviceaccount.com&Signature=N%2FaBkzixwUvbcZX49uOjFkBk4rwwFBy1bo2CTIxcrVLHWlDgPEZVrzuWJVoVccVy9PWFquAJGIxQrsqsGv9Znvtjr7BjQxijiMf6uf6z9L56VQOuWXa6IdER9AtVUmWAFARtQvUa1kGTuV5QGxyL70Y1idm1KH9ll4Zv9LiQGGzHPTg4FJE%2BxgQ7gRzr9%2Ft1vvgvmTz3Zqv5VO%2BQHECWdXC%2F4A%2B%2BprWK4W%2FzB%2FSIEdGlwNEH%2Bj4%2F0rs1bE3JeeVhNDBbahv3%2BtKG701PuCKm2oqcV2EmWqFR7Z8bzVJuVAzg4uvkV5ZMErVeTG9SRiU4dU9nFMWwp8GRlWZbS2LeWg%3D%3D: ('Connection aborted.', TimeoutError(10060, '由于连接方在一段时间后没有正确答复或连接的主机没有反应，连接尝试失败。', None, 10060, None))
2024-06-18 17:09:43,541 ERROR   wandb-upload_2:25680 [internal_api.py:upload_file():2498] upload_file request headers: {'User-Agent': 'python-requests/2.31.0', 'Accept-Encoding': 'gzip, deflate, br', 'Accept': '*/*', 'Connection': 'keep-alive', 'Content-Length': '8019'}
2024-06-18 17:09:43,541 ERROR   wandb-upload_2:25680 [internal_api.py:upload_file():2500] upload_file response body: 
2024-06-18 17:09:43,541 INFO    wandb-upload_2:25680 [retry.py:__call__():172] Retry attempt failed:
Traceback (most recent call last):
  File "D:\Reseach Software\envs\fl\lib\site-packages\urllib3\connectionpool.py", line 805, in urlopen
    **response_kw,
  File "D:\Reseach Software\envs\fl\lib\site-packages\urllib3\connectionpool.py", line 537, in _make_request
    response = conn.getresponse()
  File "D:\Reseach Software\envs\fl\lib\site-packages\urllib3\connection.py", line 466, in getresponse
    httplib_response = super().getresponse()
  File "D:\Reseach Software\envs\fl\lib\http\client.py", line 1373, in getresponse
    response.begin()
  File "D:\Reseach Software\envs\fl\lib\http\client.py", line 319, in begin
    version, status, reason = self._read_status()
  File "D:\Reseach Software\envs\fl\lib\http\client.py", line 280, in _read_status
    line = str(self.fp.readline(_MAXLINE + 1), "iso-8859-1")
  File "D:\Reseach Software\envs\fl\lib\socket.py", line 589, in readinto
    return self._sock.recv_into(b)
  File "D:\Reseach Software\envs\fl\lib\ssl.py", line 1071, in recv_into
    return self.read(nbytes, buffer)
  File "D:\Reseach Software\envs\fl\lib\ssl.py", line 929, in read
    return self._sslobj.read(len, buffer)
TimeoutError: [WinError 10060] 由于连接方在一段时间后没有正确答复或连接的主机没有反应，连接尝试失败。

During handling of the above exception, another exception occurred:

Traceback (most recent call last):
  File "D:\Reseach Software\envs\fl\lib\site-packages\requests\adapters.py", line 497, in send
    chunked=chunked,
  File "D:\Reseach Software\envs\fl\lib\site-packages\urllib3\connectionpool.py", line 848, in urlopen
    method, url, error=new_e, _pool=self, _stacktrace=sys.exc_info()[2]
  File "D:\Reseach Software\envs\fl\lib\site-packages\urllib3\util\retry.py", line 470, in increment
    raise reraise(type(error), error, _stacktrace)
  File "D:\Reseach Software\envs\fl\lib\site-packages\urllib3\util\util.py", line 38, in reraise
    raise value.with_traceback(tb)
  File "D:\Reseach Software\envs\fl\lib\site-packages\urllib3\connectionpool.py", line 805, in urlopen
    **response_kw,
  File "D:\Reseach Software\envs\fl\lib\site-packages\urllib3\connectionpool.py", line 537, in _make_request
    response = conn.getresponse()
  File "D:\Reseach Software\envs\fl\lib\site-packages\urllib3\connection.py", line 466, in getresponse
    httplib_response = super().getresponse()
  File "D:\Reseach Software\envs\fl\lib\http\client.py", line 1373, in getresponse
    response.begin()
  File "D:\Reseach Software\envs\fl\lib\http\client.py", line 319, in begin
    version, status, reason = self._read_status()
  File "D:\Reseach Software\envs\fl\lib\http\client.py", line 280, in _read_status
    line = str(self.fp.readline(_MAXLINE + 1), "iso-8859-1")
  File "D:\Reseach Software\envs\fl\lib\socket.py", line 589, in readinto
    return self._sock.recv_into(b)
  File "D:\Reseach Software\envs\fl\lib\ssl.py", line 1071, in recv_into
    return self.read(nbytes, buffer)
  File "D:\Reseach Software\envs\fl\lib\ssl.py", line 929, in read
    return self._sslobj.read(len, buffer)
urllib3.exceptions.ProtocolError: ('Connection aborted.', TimeoutError(10060, '由于连接方在一段时间后没有正确答复或连接的主机没有反应，连接尝试失败。', None, 10060, None))

During handling of the above exception, another exception occurred:

Traceback (most recent call last):
  File "D:\Reseach Software\envs\fl\lib\site-packages\wandb\sdk\internal\internal_api.py", line 2492, in upload_file
    url, data=progress, headers=extra_headers
  File "D:\Reseach Software\envs\fl\lib\site-packages\requests\sessions.py", line 649, in put
    return self.request("PUT", url, data=data, **kwargs)
  File "D:\Reseach Software\envs\fl\lib\site-packages\requests\sessions.py", line 589, in request
    resp = self.send(prep, **send_kwargs)
  File "D:\Reseach Software\envs\fl\lib\site-packages\requests\sessions.py", line 703, in send
    r = adapter.send(request, **kwargs)
  File "D:\Reseach Software\envs\fl\lib\site-packages\requests\adapters.py", line 501, in send
    raise ConnectionError(err, request=request)
requests.exceptions.ConnectionError: ('Connection aborted.', TimeoutError(10060, '由于连接方在一段时间后没有正确答复或连接的主机没有反应，连接尝试失败。', None, 10060, None))

During handling of the above exception, another exception occurred:

Traceback (most recent call last):
  File "D:\Reseach Software\envs\fl\lib\site-packages\wandb\sdk\lib\retry.py", line 131, in __call__
    result = self._call_fn(*args, **kwargs)
  File "D:\Reseach Software\envs\fl\lib\site-packages\wandb\sdk\internal\internal_api.py", line 2520, in upload_file
    raise _e.with_traceback(sys.exc_info()[2])
  File "D:\Reseach Software\envs\fl\lib\site-packages\wandb\sdk\internal\internal_api.py", line 2492, in upload_file
    url, data=progress, headers=extra_headers
  File "D:\Reseach Software\envs\fl\lib\site-packages\requests\sessions.py", line 649, in put
    return self.request("PUT", url, data=data, **kwargs)
  File "D:\Reseach Software\envs\fl\lib\site-packages\requests\sessions.py", line 589, in request
    resp = self.send(prep, **send_kwargs)
  File "D:\Reseach Software\envs\fl\lib\site-packages\requests\sessions.py", line 703, in send
    r = adapter.send(request, **kwargs)
  File "D:\Reseach Software\envs\fl\lib\site-packages\requests\adapters.py", line 501, in send
    raise ConnectionError(err, request=request)
wandb.sdk.lib.retry.TransientError: None
2024-06-18 17:09:47,670 DEBUG   HandlerThread:25680 [handler.py:handle_request():144] handle_request: stop_status
2024-06-18 17:09:47,671 DEBUG   SenderThread:25680 [sender.py:send_request():406] send_request: stop_status
2024-06-18 17:09:48,855 DEBUG   HandlerThread:25680 [handler.py:handle_request():144] handle_request: status_report
2024-06-18 17:09:48,856 DEBUG   HandlerThread:25680 [handler.py:handle_request():144] handle_request: partial_history
2024-06-18 17:09:48,857 DEBUG   SenderThread:25680 [sender.py:send():379] send: history
2024-06-18 17:09:48,857 DEBUG   SenderThread:25680 [sender.py:send_request():406] send_request: summary_record
2024-06-18 17:09:48,858 INFO    SenderThread:25680 [sender.py:_save_file():1375] saving file wandb-summary.json with policy end
2024-06-18 17:09:49,453 INFO    Thread-16 :25680 [dir_watcher.py:_on_file_modified():288] file/dir modified: D:\Research-Projects-jupyter\PFLlib\system\wandb\run-20240618_170900-ecr8evyz\files\wandb-summary.json
2024-06-18 17:09:50,461 INFO    Thread-16 :25680 [dir_watcher.py:_on_file_modified():288] file/dir modified: D:\Research-Projects-jupyter\PFLlib\system\wandb\run-20240618_170900-ecr8evyz\files\output.log
2024-06-18 17:09:53,902 DEBUG   HandlerThread:25680 [handler.py:handle_request():144] handle_request: status_report
2024-06-18 17:09:58,968 DEBUG   HandlerThread:25680 [handler.py:handle_request():144] handle_request: status_report
2024-06-18 17:10:01,597 DEBUG   SystemMonitor:25680 [system_monitor.py:_start():159] Starting system metrics aggregation loop
2024-06-18 17:10:01,597 DEBUG   SenderThread:25680 [sender.py:send():379] send: stats
2024-06-18 17:10:02,675 DEBUG   HandlerThread:25680 [handler.py:handle_request():144] handle_request: stop_status
2024-06-18 17:10:02,676 DEBUG   SenderThread:25680 [sender.py:send_request():406] send_request: stop_status
2024-06-18 17:10:04,980 DEBUG   HandlerThread:25680 [handler.py:handle_request():144] handle_request: status_report
2024-06-18 17:10:05,517 ERROR   wandb-upload_2:25680 [internal_api.py:upload_file():2496] upload_file exception https://storage.googleapis.com/wandb-production.appspot.com/paddeyzhang/SCL_test/ecr8evyz/diff.patch?Expires=1718788147&GoogleAccessId=gorilla-files-url-signer-man%40wandb-production.iam.gserviceaccount.com&Signature=N%2FaBkzixwUvbcZX49uOjFkBk4rwwFBy1bo2CTIxcrVLHWlDgPEZVrzuWJVoVccVy9PWFquAJGIxQrsqsGv9Znvtjr7BjQxijiMf6uf6z9L56VQOuWXa6IdER9AtVUmWAFARtQvUa1kGTuV5QGxyL70Y1idm1KH9ll4Zv9LiQGGzHPTg4FJE%2BxgQ7gRzr9%2Ft1vvgvmTz3Zqv5VO%2BQHECWdXC%2F4A%2B%2BprWK4W%2FzB%2FSIEdGlwNEH%2Bj4%2F0rs1bE3JeeVhNDBbahv3%2BtKG701PuCKm2oqcV2EmWqFR7Z8bzVJuVAzg4uvkV5ZMErVeTG9SRiU4dU9nFMWwp8GRlWZbS2LeWg%3D%3D: ('Connection aborted.', TimeoutError(10060, '由于连接方在一段时间后没有正确答复或连接的主机没有反应，连接尝试失败。', None, 10060, None))
2024-06-18 17:10:05,517 ERROR   wandb-upload_2:25680 [internal_api.py:upload_file():2498] upload_file request headers: {'User-Agent': 'python-requests/2.31.0', 'Accept-Encoding': 'gzip, deflate, br', 'Accept': '*/*', 'Connection': 'keep-alive', 'Content-Length': '8019'}
2024-06-18 17:10:05,517 ERROR   wandb-upload_2:25680 [internal_api.py:upload_file():2500] upload_file response body: 
2024-06-18 17:10:06,339 INFO    wandb-upload_1:25680 [upload_job.py:push():131] Uploaded file C:\Users\ly\AppData\Local\Temp\tmpt8hd81amwandb\w6d938kx-code/system/main.py
2024-06-18 17:10:10,036 DEBUG   HandlerThread:25680 [handler.py:handle_request():144] handle_request: status_report
2024-06-18 17:10:10,388 INFO    wandb-upload_2:25680 [upload_job.py:push():131] Uploaded file C:\Users\ly\AppData\Local\Temp\tmpt8hd81amwandb\kpj87rrq-diff.patch
2024-06-18 17:10:15,091 DEBUG   HandlerThread:25680 [handler.py:handle_request():144] handle_request: status_report
2024-06-18 17:10:17,673 DEBUG   HandlerThread:25680 [handler.py:handle_request():144] handle_request: stop_status
2024-06-18 17:10:17,674 DEBUG   SenderThread:25680 [sender.py:send_request():406] send_request: stop_status
2024-06-18 17:10:21,005 DEBUG   HandlerThread:25680 [handler.py:handle_request():144] handle_request: status_report
2024-06-18 17:10:26,039 DEBUG   HandlerThread:25680 [handler.py:handle_request():144] handle_request: status_report
2024-06-18 17:10:28,834 INFO    Thread-16 :25680 [dir_watcher.py:_on_file_modified():288] file/dir modified: D:\Research-Projects-jupyter\PFLlib\system\wandb\run-20240618_170900-ecr8evyz\files\output.log
2024-06-18 17:10:31,611 DEBUG   SenderThread:25680 [sender.py:send():379] send: stats
2024-06-18 17:10:31,612 DEBUG   HandlerThread:25680 [handler.py:handle_request():144] handle_request: status_report
2024-06-18 17:10:32,673 DEBUG   HandlerThread:25680 [handler.py:handle_request():144] handle_request: stop_status
2024-06-18 17:10:32,674 DEBUG   SenderThread:25680 [sender.py:send_request():406] send_request: stop_status
2024-06-18 17:10:36,970 DEBUG   HandlerThread:25680 [handler.py:handle_request():144] handle_request: status_report
2024-06-18 17:10:42,037 DEBUG   HandlerThread:25680 [handler.py:handle_request():144] handle_request: status_report
2024-06-18 17:10:47,078 DEBUG   HandlerThread:25680 [handler.py:handle_request():144] handle_request: status_report
2024-06-18 17:10:47,677 DEBUG   HandlerThread:25680 [handler.py:handle_request():144] handle_request: stop_status
2024-06-18 17:10:47,678 DEBUG   SenderThread:25680 [sender.py:send_request():406] send_request: stop_status
2024-06-18 17:10:53,020 DEBUG   HandlerThread:25680 [handler.py:handle_request():144] handle_request: status_report
2024-06-18 17:10:58,048 DEBUG   HandlerThread:25680 [handler.py:handle_request():144] handle_request: status_report
2024-06-18 17:11:01,626 DEBUG   SenderThread:25680 [sender.py:send():379] send: stats
2024-06-18 17:11:02,697 DEBUG   HandlerThread:25680 [handler.py:handle_request():144] handle_request: stop_status
2024-06-18 17:11:02,698 DEBUG   SenderThread:25680 [sender.py:send_request():406] send_request: stop_status
2024-06-18 17:11:03,936 DEBUG   HandlerThread:25680 [handler.py:handle_request():144] handle_request: status_report
2024-06-18 17:11:07,114 INFO    Thread-16 :25680 [dir_watcher.py:_on_file_modified():288] file/dir modified: D:\Research-Projects-jupyter\PFLlib\system\wandb\run-20240618_170900-ecr8evyz\files\output.log
2024-06-18 17:11:09,879 DEBUG   HandlerThread:25680 [handler.py:handle_request():144] handle_request: status_report
2024-06-18 17:11:14,909 DEBUG   HandlerThread:25680 [handler.py:handle_request():144] handle_request: status_report
2024-06-18 17:11:17,720 DEBUG   HandlerThread:25680 [handler.py:handle_request():144] handle_request: stop_status
2024-06-18 17:11:17,720 DEBUG   SenderThread:25680 [sender.py:send_request():406] send_request: stop_status
2024-06-18 17:11:19,972 DEBUG   HandlerThread:25680 [handler.py:handle_request():144] handle_request: status_report
2024-06-18 17:11:24,998 DEBUG   HandlerThread:25680 [handler.py:handle_request():144] handle_request: status_report
2024-06-18 17:11:30,020 DEBUG   HandlerThread:25680 [handler.py:handle_request():144] handle_request: status_report
2024-06-18 17:11:31,640 DEBUG   SenderThread:25680 [sender.py:send():379] send: stats
2024-06-18 17:11:32,734 DEBUG   HandlerThread:25680 [handler.py:handle_request():144] handle_request: stop_status
2024-06-18 17:11:32,735 DEBUG   SenderThread:25680 [sender.py:send_request():406] send_request: stop_status
2024-06-18 17:11:35,974 DEBUG   HandlerThread:25680 [handler.py:handle_request():144] handle_request: status_report
2024-06-18 17:11:40,988 DEBUG   HandlerThread:25680 [handler.py:handle_request():144] handle_request: status_report
2024-06-18 17:11:45,382 INFO    Thread-16 :25680 [dir_watcher.py:_on_file_modified():288] file/dir modified: D:\Research-Projects-jupyter\PFLlib\system\wandb\run-20240618_170900-ecr8evyz\files\output.log
2024-06-18 17:11:46,776 DEBUG   HandlerThread:25680 [handler.py:handle_request():144] handle_request: status_report
2024-06-18 17:11:47,746 DEBUG   HandlerThread:25680 [handler.py:handle_request():144] handle_request: stop_status
2024-06-18 17:11:47,746 DEBUG   SenderThread:25680 [sender.py:send_request():406] send_request: stop_status
2024-06-18 17:11:52,100 DEBUG   HandlerThread:25680 [handler.py:handle_request():144] handle_request: status_report
2024-06-18 17:11:57,150 DEBUG   HandlerThread:25680 [handler.py:handle_request():144] handle_request: status_report
2024-06-18 17:12:01,644 DEBUG   SenderThread:25680 [sender.py:send():379] send: stats
2024-06-18 17:12:02,645 DEBUG   HandlerThread:25680 [handler.py:handle_request():144] handle_request: status_report
2024-06-18 17:12:02,756 DEBUG   HandlerThread:25680 [handler.py:handle_request():144] handle_request: stop_status
2024-06-18 17:12:02,757 DEBUG   SenderThread:25680 [sender.py:send_request():406] send_request: stop_status
2024-06-18 17:12:08,125 DEBUG   HandlerThread:25680 [handler.py:handle_request():144] handle_request: status_report
2024-06-18 17:12:13,170 DEBUG   HandlerThread:25680 [handler.py:handle_request():144] handle_request: status_report
2024-06-18 17:12:17,777 DEBUG   HandlerThread:25680 [handler.py:handle_request():144] handle_request: stop_status
2024-06-18 17:12:17,777 DEBUG   SenderThread:25680 [sender.py:send_request():406] send_request: stop_status
2024-06-18 17:12:19,044 DEBUG   HandlerThread:25680 [handler.py:handle_request():144] handle_request: status_report
2024-06-18 17:12:23,720 INFO    Thread-16 :25680 [dir_watcher.py:_on_file_modified():288] file/dir modified: D:\Research-Projects-jupyter\PFLlib\system\wandb\run-20240618_170900-ecr8evyz\files\output.log
2024-06-18 17:12:24,692 DEBUG   HandlerThread:25680 [handler.py:handle_request():144] handle_request: status_report
